2021-08-18 14:27:55,097 (72194/MainThread) pgcli.main INFO - Default pager found in PAGER environment variable: "less"
2021-08-18 14:27:55,125 (72194/MainThread) pgcli.main ERROR - traceback: 'Traceback (most recent call last):\n  File "/usr/lib/python3.9/site-packages/pgcli/main.py", line 582, in connect\n    raise e\n  File "/usr/lib/python3.9/site-packages/pgcli/main.py", line 569, in connect\n    pgexecute = PGExecute(database, user, passwd, host, port, dsn, **kwargs)\n  File "/usr/lib/python3.9/site-packages/pgcli/pgexecute.py", line 214, in __init__\n    self.connect(database, user, password, host, port, dsn, **kwargs)\n  File "/usr/lib/python3.9/site-packages/pgcli/pgexecute.py", line 254, in connect\n    conn = psycopg2.connect(**conn_params)\n  File "/usr/lib/python3.9/site-packages/psycopg2/__init__.py", line 122, in connect\n    conn = _connect(dsn, connection_factory=connection_factory, **kwasync)\n  File "/usr/lib/python3.9/site-packages/pgcli/pgexecute.py", line 39, in _wait_select\n    state = conn.poll()\npsycopg2.OperationalError: FATAL:  role "george" does not exist\n\n'
2021-08-18 14:28:31,859 (72295/MainThread) pgcli.main INFO - Default pager found in PAGER environment variable: "less"
2021-08-18 14:29:39,844 (72295/MainThread) pgcli.pgexecute ERROR - sql: 'SELECT * FROM public.product | less', error: SyntaxError('syntax error at or near "|"\nLINE 1: SELECT * FROM public.product | less\n                                     ^\n')
2021-08-18 14:29:39,845 (72295/MainThread) pgcli.pgexecute ERROR - traceback: 'Traceback (most recent call last):\n  File "/usr/lib/python3.9/site-packages/pgcli/pgexecute.py", line 409, in run\n    yield self.execute_normal_sql(sql) + (sql, True, False)\n  File "/usr/lib/python3.9/site-packages/pgcli/pgexecute.py", line 444, in execute_normal_sql\n    cur.execute(split_sql)\npsycopg2.errors.SyntaxError: syntax error at or near "|"\nLINE 1: SELECT * FROM public.product | less\n                                     ^\n\n'
2022-06-08 10:27:15,960 (4031/MainThread) pgcli.main INFO - Default pager found in PAGER environment variable: "less"
2022-06-08 10:27:19,154 (4031/MainThread) pgcli.main ERROR - traceback: 'Traceback (most recent call last):\n  File "/usr/lib/python3.10/site-packages/pgcli/main.py", line 674, in connect\n    raise e\n  File "/usr/lib/python3.10/site-packages/pgcli/main.py", line 661, in connect\n    pgexecute = PGExecute(database, user, passwd, host, port, dsn, **kwargs)\n  File "/usr/lib/python3.10/site-packages/pgcli/pgexecute.py", line 267, in __init__\n    self.connect(database, user, password, host, port, dsn, **kwargs)\n  File "/usr/lib/python3.10/site-packages/pgcli/pgexecute.py", line 313, in connect\n    conn = psycopg2.connect(**conn_params)\n  File "/usr/lib/python3.10/site-packages/psycopg2/__init__.py", line 122, in connect\n    conn = _connect(dsn, connection_factory=connection_factory, **kwasync)\npsycopg2.OperationalError: could not connect to server: No such file or directory\n\tIs the server running locally and accepting\n\tconnections on Unix domain socket "/run/postgresql/.s.PGSQL.5432"?\n\n'
2022-06-08 10:27:58,273 (5899/MainThread) pgcli.main INFO - Default pager found in PAGER environment variable: "less"
2022-06-08 10:27:58,373 (5899/MainThread) pgcli.main ERROR - traceback: 'Traceback (most recent call last):\n  File "/usr/lib/python3.10/site-packages/pgcli/main.py", line 674, in connect\n    raise e\n  File "/usr/lib/python3.10/site-packages/pgcli/main.py", line 661, in connect\n    pgexecute = PGExecute(database, user, passwd, host, port, dsn, **kwargs)\n  File "/usr/lib/python3.10/site-packages/pgcli/pgexecute.py", line 267, in __init__\n    self.connect(database, user, password, host, port, dsn, **kwargs)\n  File "/usr/lib/python3.10/site-packages/pgcli/pgexecute.py", line 313, in connect\n    conn = psycopg2.connect(**conn_params)\n  File "/usr/lib/python3.10/site-packages/psycopg2/__init__.py", line 122, in connect\n    conn = _connect(dsn, connection_factory=connection_factory, **kwasync)\npsycopg2.OperationalError: could not connect to server: No such file or directory\n\tIs the server running locally and accepting\n\tconnections on Unix domain socket "/run/postgresql/.s.PGSQL.5432"?\n\n'
2022-06-08 10:28:37,978 (6197/MainThread) pgcli.main INFO - Default pager found in PAGER environment variable: "less"
2022-06-08 10:28:41,546 (6197/MainThread) pgcli.main ERROR - traceback: 'Traceback (most recent call last):\n  File "/usr/lib/python3.10/site-packages/pgcli/main.py", line 674, in connect\n    raise e\n  File "/usr/lib/python3.10/site-packages/pgcli/main.py", line 661, in connect\n    pgexecute = PGExecute(database, user, passwd, host, port, dsn, **kwargs)\n  File "/usr/lib/python3.10/site-packages/pgcli/pgexecute.py", line 267, in __init__\n    self.connect(database, user, password, host, port, dsn, **kwargs)\n  File "/usr/lib/python3.10/site-packages/pgcli/pgexecute.py", line 313, in connect\n    conn = psycopg2.connect(**conn_params)\n  File "/usr/lib/python3.10/site-packages/psycopg2/__init__.py", line 122, in connect\n    conn = _connect(dsn, connection_factory=connection_factory, **kwasync)\npsycopg2.OperationalError: could not translate host name "ost" to address: Name or service not known\n\n'
2022-06-14 12:30:49,406 (15307/MainThread) pgcli.main INFO - Default pager found in PAGER environment variable: "less"
2022-06-14 12:30:49,555 (15307/MainThread) pgcli.main ERROR - traceback: 'Traceback (most recent call last):\n  File "/usr/lib/python3.10/site-packages/pgcli/main.py", line 674, in connect\n    raise e\n  File "/usr/lib/python3.10/site-packages/pgcli/main.py", line 661, in connect\n    pgexecute = PGExecute(database, user, passwd, host, port, dsn, **kwargs)\n  File "/usr/lib/python3.10/site-packages/pgcli/pgexecute.py", line 267, in __init__\n    self.connect(database, user, password, host, port, dsn, **kwargs)\n  File "/usr/lib/python3.10/site-packages/pgcli/pgexecute.py", line 313, in connect\n    conn = psycopg2.connect(**conn_params)\n  File "/usr/lib/python3.10/site-packages/psycopg2/__init__.py", line 122, in connect\n    conn = _connect(dsn, connection_factory=connection_factory, **kwasync)\npsycopg2.OperationalError: could not connect to server: No such file or directory\n\tIs the server running locally and accepting\n\tconnections on Unix domain socket "/run/postgresql/.s.PGSQL.5432"?\n\n'
2022-06-14 12:31:13,614 (15397/MainThread) pgcli.main INFO - Default pager found in PAGER environment variable: "less"
2022-06-14 12:31:17,321 (15397/MainThread) pgcli.main ERROR - traceback: 'Traceback (most recent call last):\n  File "/usr/lib/python3.10/site-packages/pgcli/main.py", line 674, in connect\n    raise e\n  File "/usr/lib/python3.10/site-packages/pgcli/main.py", line 661, in connect\n    pgexecute = PGExecute(database, user, passwd, host, port, dsn, **kwargs)\n  File "/usr/lib/python3.10/site-packages/pgcli/pgexecute.py", line 267, in __init__\n    self.connect(database, user, password, host, port, dsn, **kwargs)\n  File "/usr/lib/python3.10/site-packages/pgcli/pgexecute.py", line 313, in connect\n    conn = psycopg2.connect(**conn_params)\n  File "/usr/lib/python3.10/site-packages/psycopg2/__init__.py", line 122, in connect\n    conn = _connect(dsn, connection_factory=connection_factory, **kwasync)\npsycopg2.OperationalError: could not translate host name "localhost:5432" to address: Name or service not known\n\n'
2022-06-14 12:31:40,425 (15471/MainThread) pgcli.main INFO - Default pager found in PAGER environment variable: "less"
2022-06-14 12:31:44,318 (15471/MainThread) pgcli.main ERROR - traceback: 'Traceback (most recent call last):\n  File "/usr/lib/python3.10/site-packages/pgcli/main.py", line 674, in connect\n    raise e\n  File "/usr/lib/python3.10/site-packages/pgcli/main.py", line 661, in connect\n    pgexecute = PGExecute(database, user, passwd, host, port, dsn, **kwargs)\n  File "/usr/lib/python3.10/site-packages/pgcli/pgexecute.py", line 267, in __init__\n    self.connect(database, user, password, host, port, dsn, **kwargs)\n  File "/usr/lib/python3.10/site-packages/pgcli/pgexecute.py", line 313, in connect\n    conn = psycopg2.connect(**conn_params)\n  File "/usr/lib/python3.10/site-packages/psycopg2/__init__.py", line 122, in connect\n    conn = _connect(dsn, connection_factory=connection_factory, **kwasync)\npsycopg2.OperationalError: could not translate host name "localhost:54321" to address: Name or service not known\n\n'
2022-06-14 12:31:56,052 (15511/MainThread) pgcli.main INFO - Default pager found in PAGER environment variable: "less"
2022-06-14 12:32:02,770 (15536/MainThread) pgcli.main INFO - Default pager found in PAGER environment variable: "less"
2022-06-14 12:32:02,860 (15536/MainThread) pgcli.main ERROR - traceback: 'Traceback (most recent call last):\n  File "/usr/lib/python3.10/site-packages/pgcli/main.py", line 674, in connect\n    raise e\n  File "/usr/lib/python3.10/site-packages/pgcli/main.py", line 661, in connect\n    pgexecute = PGExecute(database, user, passwd, host, port, dsn, **kwargs)\n  File "/usr/lib/python3.10/site-packages/pgcli/pgexecute.py", line 267, in __init__\n    self.connect(database, user, password, host, port, dsn, **kwargs)\n  File "/usr/lib/python3.10/site-packages/pgcli/pgexecute.py", line 313, in connect\n    conn = psycopg2.connect(**conn_params)\n  File "/usr/lib/python3.10/site-packages/psycopg2/__init__.py", line 122, in connect\n    conn = _connect(dsn, connection_factory=connection_factory, **kwasync)\npsycopg2.OperationalError: could not connect to server: Connection refused\n\tIs the server running on host "localhost" (::1) and accepting\n\tTCP/IP connections on port 54321?\ncould not connect to server: Connection refused\n\tIs the server running on host "localhost" (127.0.0.1) and accepting\n\tTCP/IP connections on port 54321?\n\n'
2022-06-14 12:32:05,728 (15567/MainThread) pgcli.main INFO - Default pager found in PAGER environment variable: "less"
2022-06-14 12:32:58,379 (15567/MainThread) pgcli.pgexecute ERROR - sql: 'tables', error: SyntaxError('syntax error at or near "tables"\nLINE 1: tables\n        ^\n')
2022-06-14 12:32:58,379 (15567/MainThread) pgcli.pgexecute ERROR - traceback: 'Traceback (most recent call last):\n  File "/usr/lib/python3.10/site-packages/pgcli/pgexecute.py", line 480, in run\n    yield self.execute_normal_sql(sql) + (sql, True, False)\n  File "/usr/lib/python3.10/site-packages/pgcli/pgexecute.py", line 515, in execute_normal_sql\n    cur.execute(split_sql)\n  File "/usr/lib/python3.10/site-packages/pgcli/pgexecute.py", line 175, in execute\n    psycopg2.extensions.cursor.execute(self, sql, args)\npsycopg2.errors.SyntaxError: syntax error at or near "tables"\nLINE 1: tables\n        ^\n\n'
2022-06-14 12:33:28,738 (15567/MainThread) pgcli.pgexecute ERROR - sql: '/h', error: SyntaxError('syntax error at or near "/"\nLINE 1: /h\n        ^\n')
2022-06-14 12:33:28,739 (15567/MainThread) pgcli.pgexecute ERROR - traceback: 'Traceback (most recent call last):\n  File "/usr/lib/python3.10/site-packages/pgcli/pgexecute.py", line 480, in run\n    yield self.execute_normal_sql(sql) + (sql, True, False)\n  File "/usr/lib/python3.10/site-packages/pgcli/pgexecute.py", line 515, in execute_normal_sql\n    cur.execute(split_sql)\n  File "/usr/lib/python3.10/site-packages/pgcli/pgexecute.py", line 175, in execute\n    psycopg2.extensions.cursor.execute(self, sql, args)\npsycopg2.errors.SyntaxError: syntax error at or near "/"\nLINE 1: /h\n        ^\n\n'
2022-06-14 12:33:30,168 (15567/MainThread) pgcli.pgexecute ERROR - sql: 'help', error: SyntaxError('syntax error at or near "help"\nLINE 1: help\n        ^\n')
2022-06-14 12:33:30,168 (15567/MainThread) pgcli.pgexecute ERROR - traceback: 'Traceback (most recent call last):\n  File "/usr/lib/python3.10/site-packages/pgcli/pgexecute.py", line 480, in run\n    yield self.execute_normal_sql(sql) + (sql, True, False)\n  File "/usr/lib/python3.10/site-packages/pgcli/pgexecute.py", line 515, in execute_normal_sql\n    cur.execute(split_sql)\n  File "/usr/lib/python3.10/site-packages/pgcli/pgexecute.py", line 175, in execute\n    psycopg2.extensions.cursor.execute(self, sql, args)\npsycopg2.errors.SyntaxError: syntax error at or near "help"\nLINE 1: help\n        ^\n\n'
2022-06-14 12:35:18,102 (16624/MainThread) pgcli.main INFO - Default pager found in PAGER environment variable: "less"
2022-06-14 12:35:21,790 (16624/MainThread) pgcli.pgexecute ERROR - sql: '\\t', error: SyntaxError('syntax error at or near "\\"\nLINE 1: \\t\n        ^\n')
2022-06-14 12:35:21,790 (16624/MainThread) pgcli.pgexecute ERROR - traceback: 'Traceback (most recent call last):\n  File "/usr/lib/python3.10/site-packages/pgcli/pgexecute.py", line 480, in run\n    yield self.execute_normal_sql(sql) + (sql, True, False)\n  File "/usr/lib/python3.10/site-packages/pgcli/pgexecute.py", line 515, in execute_normal_sql\n    cur.execute(split_sql)\n  File "/usr/lib/python3.10/site-packages/pgcli/pgexecute.py", line 175, in execute\n    psycopg2.extensions.cursor.execute(self, sql, args)\npsycopg2.errors.SyntaxError: syntax error at or near "\\"\nLINE 1: \\t\n        ^\n\n'
2022-06-14 12:37:55,336 (17502/MainThread) pgcli.main INFO - Default pager found in PAGER environment variable: "less"
2022-06-14 12:41:11,340 (19554/MainThread) pgcli.main INFO - Default pager found in PAGER environment variable: "less"
2022-07-06 16:07:47,121 (2325/MainThread) pgcli.main INFO - Default pager found in PAGER environment variable: "less"
2022-07-06 16:07:47,243 (2325/MainThread) pgcli.main ERROR - traceback: 'Traceback (most recent call last):\n  File "/usr/lib/python3.10/site-packages/pgcli/main.py", line 674, in connect\n    raise e\n  File "/usr/lib/python3.10/site-packages/pgcli/main.py", line 661, in connect\n    pgexecute = PGExecute(database, user, passwd, host, port, dsn, **kwargs)\n  File "/usr/lib/python3.10/site-packages/pgcli/pgexecute.py", line 267, in __init__\n    self.connect(database, user, password, host, port, dsn, **kwargs)\n  File "/usr/lib/python3.10/site-packages/pgcli/pgexecute.py", line 313, in connect\n    conn = psycopg2.connect(**conn_params)\n  File "/usr/lib/python3.10/site-packages/psycopg2/__init__.py", line 122, in connect\n    conn = _connect(dsn, connection_factory=connection_factory, **kwasync)\npsycopg2.OperationalError: could not connect to server: Connection refused\n\tIs the server running on host "localhost" (::1) and accepting\n\tTCP/IP connections on port 5432?\ncould not connect to server: Connection refused\n\tIs the server running on host "localhost" (127.0.0.1) and accepting\n\tTCP/IP connections on port 5432?\n\n'
2022-07-06 16:19:11,306 (9915/MainThread) pgcli.main INFO - Default pager found in PAGER environment variable: "less"
2022-07-06 16:19:35,013 (9915/MainThread) pgcli.pgexecute ERROR - sql: 'SELECT * FROM public.product | less LIMIT 2', error: SyntaxError('syntax error at or near "|"\nLINE 1: SELECT * FROM public.product | less LIMIT 2\n                                     ^\n')
2022-07-06 16:19:35,014 (9915/MainThread) pgcli.pgexecute ERROR - traceback: 'Traceback (most recent call last):\n  File "/usr/lib/python3.10/site-packages/pgcli/pgexecute.py", line 480, in run\n    yield self.execute_normal_sql(sql) + (sql, True, False)\n  File "/usr/lib/python3.10/site-packages/pgcli/pgexecute.py", line 515, in execute_normal_sql\n    cur.execute(split_sql)\n  File "/usr/lib/python3.10/site-packages/pgcli/pgexecute.py", line 175, in execute\n    psycopg2.extensions.cursor.execute(self, sql, args)\npsycopg2.errors.SyntaxError: syntax error at or near "|"\nLINE 1: SELECT * FROM public.product | less LIMIT 2\n                                     ^\n\n'
2022-07-12 12:06:57,041 (25450/MainThread) pgcli.main INFO - Default pager found in PAGER environment variable: "less"
2022-07-12 12:08:28,789 (25450/MainThread) pgcli.pgexecute ERROR - sql: 'SELECT id from reaction >>', error: SyntaxError('syntax error at or near ">>"\nLINE 1: SELECT id from reaction >>\n                                ^\n')
2022-07-12 12:08:28,789 (25450/MainThread) pgcli.pgexecute ERROR - traceback: 'Traceback (most recent call last):\n  File "/usr/lib/python3.10/site-packages/pgcli/pgexecute.py", line 480, in run\n    yield self.execute_normal_sql(sql) + (sql, True, False)\n  File "/usr/lib/python3.10/site-packages/pgcli/pgexecute.py", line 515, in execute_normal_sql\n    cur.execute(split_sql)\n  File "/usr/lib/python3.10/site-packages/pgcli/pgexecute.py", line 175, in execute\n    psycopg2.extensions.cursor.execute(self, sql, args)\npsycopg2.errors.SyntaxError: syntax error at or near ">>"\nLINE 1: SELECT id from reaction >>\n                                ^\n\n'
2022-07-27 15:52:35,738 (37332/MainThread) pgcli.main INFO - Default pager found in PAGER environment variable: "less"
2022-07-28 10:34:39,150 (7417/MainThread) pgcli.main INFO - Default pager found in PAGER environment variable: "less"
2022-07-28 10:34:45,898 (7417/MainThread) pgcli.pgexecute ERROR - sql: 'sele', error: SyntaxError('syntax error at or near "sele"\nLINE 1: sele\n        ^\n')
2022-07-28 10:34:45,899 (7417/MainThread) pgcli.pgexecute ERROR - traceback: 'Traceback (most recent call last):\n  File "/usr/lib/python3.10/site-packages/pgcli/pgexecute.py", line 480, in run\n    yield self.execute_normal_sql(sql) + (sql, True, False)\n  File "/usr/lib/python3.10/site-packages/pgcli/pgexecute.py", line 515, in execute_normal_sql\n    cur.execute(split_sql)\n  File "/usr/lib/python3.10/site-packages/pgcli/pgexecute.py", line 175, in execute\n    psycopg2.extensions.cursor.execute(self, sql, args)\npsycopg2.errors.SyntaxError: syntax error at or near "sele"\nLINE 1: sele\n        ^\n\n'
2022-09-06 11:38:55,496 (21279/MainThread) pgcli.main INFO - Default pager found in PAGER environment variable: "less"
2022-09-06 11:39:52,998 (21279/MainThread) pgcli.pgexecute ERROR - sql: 'select * from design where user_id="ol3clo.fzcmpy2"', error: UndefinedColumn('column "ol3clo.fzcmpy2" does not exist\nLINE 1: select * from design where user_id="ol3clo.fzcmpy2"\n                                           ^\n')
2022-09-06 11:39:52,999 (21279/MainThread) pgcli.pgexecute ERROR - traceback: 'Traceback (most recent call last):\n  File "/usr/lib/python3.10/site-packages/pgcli/pgexecute.py", line 480, in run\n    yield self.execute_normal_sql(sql) + (sql, True, False)\n  File "/usr/lib/python3.10/site-packages/pgcli/pgexecute.py", line 515, in execute_normal_sql\n    cur.execute(split_sql)\n  File "/usr/lib/python3.10/site-packages/pgcli/pgexecute.py", line 175, in execute\n    psycopg2.extensions.cursor.execute(self, sql, args)\npsycopg2.errors.UndefinedColumn: column "ol3clo.fzcmpy2" does not exist\nLINE 1: select * from design where user_id="ol3clo.fzcmpy2"\n                                           ^\n\n'
2022-09-21 12:14:44,659 (12299/MainThread) pgcli.main INFO - Default pager found in PAGER environment variable: "less"
2022-09-21 12:14:44,795 (12299/MainThread) pgcli.main ERROR - traceback: 'Traceback (most recent call last):\n  File "/usr/lib/python3.10/site-packages/pgcli/main.py", line 640, in connect\n    raise e\n  File "/usr/lib/python3.10/site-packages/pgcli/main.py", line 627, in connect\n    pgexecute = PGExecute(database, user, passwd, host, port, dsn, **kwargs)\n  File "/usr/lib/python3.10/site-packages/pgcli/pgexecute.py", line 161, in __init__\n    self.connect(database, user, password, host, port, dsn, **kwargs)\n  File "/usr/lib/python3.10/site-packages/pgcli/pgexecute.py", line 207, in connect\n    conn = psycopg.connect(conn_info)\n  File "/usr/lib/python3.10/site-packages/psycopg/connection.py", line 725, in connect\n    raise ex.with_traceback(None)\npsycopg.OperationalError: connection failed: Connection refused\n\tIs the server running on host "localhost" (::1) and accepting\n\tTCP/IP connections on port 5432?\ncould not connect to server: Connection refused\n\tIs the server running on host "localhost" (127.0.0.1) and accepting\n\tTCP/IP connections on port 5432?\n'
2022-09-21 12:15:06,544 (13171/MainThread) pgcli.main INFO - Default pager found in PAGER environment variable: "less"
2022-09-21 12:15:06,619 (13171/MainThread) pgcli.main ERROR - traceback: 'Traceback (most recent call last):\n  File "/usr/lib/python3.10/site-packages/pgcli/main.py", line 640, in connect\n    raise e\n  File "/usr/lib/python3.10/site-packages/pgcli/main.py", line 627, in connect\n    pgexecute = PGExecute(database, user, passwd, host, port, dsn, **kwargs)\n  File "/usr/lib/python3.10/site-packages/pgcli/pgexecute.py", line 161, in __init__\n    self.connect(database, user, password, host, port, dsn, **kwargs)\n  File "/usr/lib/python3.10/site-packages/pgcli/pgexecute.py", line 207, in connect\n    conn = psycopg.connect(conn_info)\n  File "/usr/lib/python3.10/site-packages/psycopg/connection.py", line 725, in connect\n    raise ex.with_traceback(None)\npsycopg.OperationalError: connection failed: Connection refused\n\tIs the server running on host "localhost" (::1) and accepting\n\tTCP/IP connections on port 5432?\ncould not connect to server: Connection refused\n\tIs the server running on host "localhost" (127.0.0.1) and accepting\n\tTCP/IP connections on port 5432?\n'
2022-09-21 12:15:39,598 (13735/MainThread) pgcli.main INFO - Default pager found in PAGER environment variable: "less"
2022-09-21 12:15:39,672 (13735/MainThread) pgcli.main ERROR - traceback: 'Traceback (most recent call last):\n  File "/usr/lib/python3.10/site-packages/pgcli/main.py", line 640, in connect\n    raise e\n  File "/usr/lib/python3.10/site-packages/pgcli/main.py", line 627, in connect\n    pgexecute = PGExecute(database, user, passwd, host, port, dsn, **kwargs)\n  File "/usr/lib/python3.10/site-packages/pgcli/pgexecute.py", line 161, in __init__\n    self.connect(database, user, password, host, port, dsn, **kwargs)\n  File "/usr/lib/python3.10/site-packages/pgcli/pgexecute.py", line 207, in connect\n    conn = psycopg.connect(conn_info)\n  File "/usr/lib/python3.10/site-packages/psycopg/connection.py", line 725, in connect\n    raise ex.with_traceback(None)\npsycopg.OperationalError: connection failed: Connection refused\n\tIs the server running on host "localhost" (::1) and accepting\n\tTCP/IP connections on port 5432?\ncould not connect to server: Connection refused\n\tIs the server running on host "localhost" (127.0.0.1) and accepting\n\tTCP/IP connections on port 5432?\n'
2022-09-21 12:16:18,420 (13816/MainThread) pgcli.main INFO - Default pager found in PAGER environment variable: "less"
2022-09-21 12:16:18,496 (13816/MainThread) pgcli.main ERROR - traceback: 'Traceback (most recent call last):\n  File "/usr/lib/python3.10/site-packages/pgcli/main.py", line 640, in connect\n    raise e\n  File "/usr/lib/python3.10/site-packages/pgcli/main.py", line 627, in connect\n    pgexecute = PGExecute(database, user, passwd, host, port, dsn, **kwargs)\n  File "/usr/lib/python3.10/site-packages/pgcli/pgexecute.py", line 161, in __init__\n    self.connect(database, user, password, host, port, dsn, **kwargs)\n  File "/usr/lib/python3.10/site-packages/pgcli/pgexecute.py", line 207, in connect\n    conn = psycopg.connect(conn_info)\n  File "/usr/lib/python3.10/site-packages/psycopg/connection.py", line 725, in connect\n    raise ex.with_traceback(None)\npsycopg.OperationalError: connection failed: Connection refused\n\tIs the server running on host "localhost" (::1) and accepting\n\tTCP/IP connections on port 5432?\ncould not connect to server: Connection refused\n\tIs the server running on host "localhost" (127.0.0.1) and accepting\n\tTCP/IP connections on port 5432?\n'
2022-09-21 12:17:09,930 (13885/MainThread) pgcli.main INFO - Default pager found in PAGER environment variable: "less"
2022-09-21 12:17:27,453 (14295/MainThread) pgcli.main INFO - Default pager found in PAGER environment variable: "less"
2022-09-21 12:17:51,785 (14295/MainThread) pgcli.pgexecute ERROR - sql: 'select * from pla', error: UndefinedTable('relation "pla" does not exist\nLINE 1: select * from pla\n                      ^')
2022-09-21 12:17:51,786 (14295/MainThread) pgcli.pgexecute ERROR - traceback: 'Traceback (most recent call last):\n  File "/usr/lib/python3.10/site-packages/pgcli/pgexecute.py", line 373, in run\n    yield self.execute_normal_sql(sql) + (sql, True, False)\n  File "/usr/lib/python3.10/site-packages/pgcli/pgexecute.py", line 423, in execute_normal_sql\n    cur.execute(split_sql)\n  File "/usr/lib/python3.10/site-packages/pgcli/pgexecute.py", line 69, in execute\n    super().execute(*args, **kwargs)\n  File "/usr/lib/python3.10/site-packages/psycopg/cursor.py", line 725, in execute\n    raise ex.with_traceback(None)\npsycopg.errors.UndefinedTable: relation "pla" does not exist\nLINE 1: select * from pla\n                      ^\n'
2022-09-21 12:22:24,608 (19292/MainThread) pgcli.main INFO - Default pager found in PAGER environment variable: "less"
2022-10-04 10:54:53,515 (19396/MainThread) pgcli.main INFO - Default pager found in PAGER environment variable: "less"
2022-10-04 10:54:54,779 (19396/MainThread) pgcli.pgexecute ERROR - sql: 'sele', error: SyntaxError('syntax error at or near "sele"\nLINE 1: sele\n        ^')
2022-10-04 10:54:54,779 (19396/MainThread) pgcli.pgexecute ERROR - traceback: 'Traceback (most recent call last):\n  File "/usr/lib/python3.10/site-packages/pgcli/pgexecute.py", line 373, in run\n    yield self.execute_normal_sql(sql) + (sql, True, False)\n  File "/usr/lib/python3.10/site-packages/pgcli/pgexecute.py", line 423, in execute_normal_sql\n    cur.execute(split_sql)\n  File "/usr/lib/python3.10/site-packages/pgcli/pgexecute.py", line 69, in execute\n    super().execute(*args, **kwargs)\n  File "/usr/lib/python3.10/site-packages/psycopg/cursor.py", line 725, in execute\n    raise ex.with_traceback(None)\npsycopg.errors.SyntaxError: syntax error at or near "sele"\nLINE 1: sele\n        ^\n'
2022-10-04 11:56:54,102 (12758/MainThread) pgcli.main INFO - Default pager found in PAGER environment variable: "less"
2022-10-19 17:50:39,115 (68913/MainThread) pgcli.main INFO - Default pager found in PAGER environment variable: "less"
2022-10-19 17:51:08,341 (68913/MainThread) pgcli.pgexecute ERROR - sql: 'select slug from shop_config where slug like "test%"', error: UndefinedColumn('column "test%" does not exist\nLINE 1: select slug from shop_config where slug like "test%"\n                                                     ^')
2022-10-19 17:51:08,341 (68913/MainThread) pgcli.pgexecute ERROR - traceback: 'Traceback (most recent call last):\n  File "/usr/lib/python3.10/site-packages/pgcli/pgexecute.py", line 373, in run\n    yield self.execute_normal_sql(sql) + (sql, True, False)\n  File "/usr/lib/python3.10/site-packages/pgcli/pgexecute.py", line 423, in execute_normal_sql\n    cur.execute(split_sql)\n  File "/usr/lib/python3.10/site-packages/pgcli/pgexecute.py", line 69, in execute\n    super().execute(*args, **kwargs)\n  File "/usr/lib/python3.10/site-packages/psycopg/cursor.py", line 725, in execute\n    raise ex.with_traceback(None)\npsycopg.errors.UndefinedColumn: column "test%" does not exist\nLINE 1: select slug from shop_config where slug like "test%"\n                                                     ^\n'
2022-10-19 18:00:18,247 (68913/MainThread) pgcli.pgexecute ERROR - sql: "select slug from shop_config where slug like 'test-%01' or slug ='test' order", error: SyntaxError("syntax error at end of input\nLINE 1: ...shop_config where slug like 'test-%01' or slug ='test' order\n                                                                       ^")
2022-10-19 18:00:18,248 (68913/MainThread) pgcli.pgexecute ERROR - traceback: 'Traceback (most recent call last):\n  File "/usr/lib/python3.10/site-packages/pgcli/pgexecute.py", line 373, in run\n    yield self.execute_normal_sql(sql) + (sql, True, False)\n  File "/usr/lib/python3.10/site-packages/pgcli/pgexecute.py", line 423, in execute_normal_sql\n    cur.execute(split_sql)\n  File "/usr/lib/python3.10/site-packages/pgcli/pgexecute.py", line 69, in execute\n    super().execute(*args, **kwargs)\n  File "/usr/lib/python3.10/site-packages/psycopg/cursor.py", line 725, in execute\n    raise ex.with_traceback(None)\npsycopg.errors.SyntaxError: syntax error at end of input\nLINE 1: ...shop_config where slug like \'test-%01\' or slug =\'test\' order\n                                                                       ^\n'
2022-11-29 11:07:01,395 (17001/MainThread) pgcli.main INFO - Default pager found in PAGER environment variable: "less"
2022-11-29 11:07:06,226 (17001/MainThread) pgcli.pgexecute ERROR - sql: 'ls', error: SyntaxError('syntax error at or near "ls"\nLINE 1: ls\n        ^')
2022-11-29 11:07:06,227 (17001/MainThread) pgcli.pgexecute ERROR - traceback: 'Traceback (most recent call last):\n  File "/usr/lib/python3.10/site-packages/pgcli/pgexecute.py", line 373, in run\n    yield self.execute_normal_sql(sql) + (sql, True, False)\n  File "/usr/lib/python3.10/site-packages/pgcli/pgexecute.py", line 423, in execute_normal_sql\n    cur.execute(split_sql)\n  File "/usr/lib/python3.10/site-packages/pgcli/pgexecute.py", line 69, in execute\n    super().execute(*args, **kwargs)\n  File "/usr/lib/python3.10/site-packages/psycopg/cursor.py", line 725, in execute\n    raise ex.with_traceback(None)\npsycopg.errors.SyntaxError: syntax error at or near "ls"\nLINE 1: ls\n        ^\n'
